<?xml version="1.0" ?>
<robot name="r1mini" xmlns:xacro="http://ros.org/wiki/xacro">
  <xacro:include filename="$(find omo_r1mini_description)/urdf/common_properties.xacro"/>

  <link name="base_footprint"/>

  <joint name="base_joint" type="fixed">
    <parent link="base_footprint"/>
    <child link="base_link" />
    <origin xyz="0 0 0.0335" rpy="0 0 0.0"/>
  </joint>

  <link name="base_link">
    <visual>
      <origin xyz="0.03 -0.065 -0.022" rpy="0 0 1.57"/>
      <geometry>
        <mesh filename="package://omo_r1mini_description/meshes/bases/mini_frame.stl" scale="0.001 0.001 0.001"/>
      </geometry>
      <material name="dark"/>
    </visual>

    <collision>
      <origin xyz="0.03 -0.065 -0.022" rpy="0 0 1.57"/>
      <geometry>
        <mesh filename="package://omo_r1mini_description/meshes/bases/mini_frame.stl" scale="0.001 0.001 0.001"/>
      </geometry>
    </collision>

    <inertial>
      <origin xyz="-0.1 0 0" rpy="0 0 0"/>
      <mass value="1.3729096e+00"/>
      <inertia ixx="8.7002718e-03" ixy="-4.7576583e-05" ixz="1.1160499e-04"
               iyy="8.6195418e-03" iyz="-3.5422299e-06"
               izz="1.4612727e-02" />
    </inertial>
  </link>

  <joint name="housing_joint" type="fixed">
    <parent link="base_link"/>
    <child link="housing_link" />
    <origin xyz="0 0 0" rpy="0 0 0.0"/>
  </joint>

  <link name="housing_link">
    <visual>
      <origin xyz="-0.028 0 -0.028" rpy="0 0 1.57"/>
      <geometry>
        <mesh filename="package://omo_r1mini_description/meshes/bases/r1mini housing lite 2.stl" scale="0.001 0.001 0.001"/>
      </geometry>
      <material name="pink"/>
    </visual>
    <collision>
      <origin xyz="-0.028 0 -0.028" rpy="0 0 1.57"/>
      <geometry>
        <mesh filename="package://omo_r1mini_description/meshes/bases/r1mini housing lite 2.stl" scale="0.001 0.001 0.001"/>
      </geometry>
    </collision>

    <inertial>
      <origin xyz="-0.1 0 0" rpy="0 0 0"/>
      <mass value="0.01"/>
      <inertia ixx="8.7002718e-04" ixy="-4.7576583e-07" ixz="1.1160499e-07"
               iyy="8.6195418e-04" iyz="-3.5422299e-07"
               izz="1.4612727e-04" />
    </inertial>
  </link>

  <joint name="wheel_left_joint" type="continuous">
    <parent link="base_link"/>
    <child link="wheel_left_link"/>
    <origin xyz="0.0 0.096 0.0" rpy="0.0 0.0 0"/>
    <axis xyz="0 1 0"/>
  </joint>

  <link name="wheel_left_link">
    <visual>
      <origin xyz="-0.0335 -0.004 -0.0335" rpy="1.57 0 0"/>
      <geometry>
        <mesh filename="package://omo_r1mini_description/meshes/wheels/mini_tire.stl" scale="0.001 0.001 0.001"/>
      </geometry>
      <material name="dark"/>
    </visual>

    <collision>
      <origin xyz="-0.0335 -0.004 -0.0335" rpy="1.57 0 0"/>
      <geometry>
        <mesh filename="package://omo_r1mini_description/meshes/wheels/mini_tire.stl" scale="0.001 0.001 0.001"/>
      </geometry>
    </collision>

    <inertial>
      <origin xyz="0 0 0" />
      <mass value="2.8498940e-02" />
      <inertia ixx="1.1175580e-05" ixy="-4.2369783e-11" ixz="-5.9381719e-09"
               iyy="1.1192413e-05" iyz="-1.4400107e-11"
               izz="2.0712558e-05" />
    </inertial>
  </link>

  <joint name="wheel_right_joint" type="continuous">
    <parent link="base_link"/>
    <child link="wheel_right_link"/>
    <origin xyz="0.0 -0.096 0.0" rpy="0.0 0.0 0"/>
    <axis xyz="0 1 0"/>
  </joint>

  <link name="wheel_right_link">
    <visual>
      <origin xyz="-0.0335 0.004 0.0335" rpy="-1.57 0 0"/>
      <geometry>
        <mesh filename="package://omo_r1mini_description/meshes/wheels/mini_tire.stl" scale="0.001 0.001 0.001"/>
      </geometry>
      <material name="dark"/>
    </visual>
    <collision>
      <origin xyz="-0.0335 0.004 0.0335" rpy="-1.57 0 0"/>
      <geometry>
        <mesh filename="package://omo_r1mini_description/meshes/wheels/mini_tire.stl" scale="0.001 0.001 0.001"/>
      </geometry>
    </collision>
    <inertial>
      <origin xyz="0 0 0" />
      <mass value="2.8498940e-02" />
      <inertia ixx="1.1175580e-05" ixy="-4.2369783e-11" ixz="-5.9381719e-09"
               iyy="1.1192413e-05" iyz="-1.4400107e-11"
               izz="2.0712558e-05" />
    </inertial>

  </link>

  <joint name="caster_back_joint" type="fixed">
    <parent link="base_link"/>
    <child link="caster_back_link"/>
    <origin xyz="-0.12 0.0 -0.018" rpy="0 0 0"/>
  </joint>

  <link name="caster_back_link">
    <visual>
      <origin xyz="-0.016 -0.007 -0.016" rpy="0 0 0"/>
      <geometry>
        <mesh filename="package://omo_r1mini_description/meshes/wheels/mini_caster.stl" scale="0.001 0.001 0.001"/>
      </geometry>
      <material name="dark"/>
    </visual>
    <collision>
      <origin xyz="-0.016 -0.007 -0.016" rpy="0 0 0"/>
      <geometry>
        <mesh filename="package://omo_r1mini_description/meshes/wheels/mini_caster.stl" scale="0.001 0.001 0.001"/>
      </geometry>
    </collision>

    <inertial>
      <origin xyz="0 0 0" />
      <mass value="0.005" />
      <inertia ixx="0.001" ixy="0.0" ixz="0.0"
               iyy="0.001" iyz="0.0"
               izz="0.001" />
    </inertial>
  </link>

  <joint name="imu_joint" type="fixed">
    <parent link="base_link"/>
    <child link="imu_link"/>
    <origin xyz="0.0 0 0.038" rpy="0 0 0"/>
  </joint>

  <link name="imu_link"/>

  <joint name="scan_joint" type="fixed">
    <parent link="base_link"/>
    <child link="base_scan"/>
    <origin xyz="0.0 0 0.07" rpy="0.0 0 3.14159"/>
  </joint>

  <link name="base_scan">
    <visual>
      <origin xyz="0 0 0.0" rpy="0 0 0"/>
      <geometry>
        <mesh filename="package://omo_r1mini_description/meshes/sensors/lds.stl" scale="0.001 0.001 0.001"/>
      </geometry>
      <material name="dark"/>
    </visual>

    <collision>
      <origin xyz="0.015 0 -0.0065" rpy="0 0 0"/>
      <geometry>
        <cylinder length="0.0315" radius="0.055"/>
      </geometry>
    </collision>

    <inertial>
      <mass value="0.05" />
      <origin xyz="0 0 0" />
      <inertia ixx="0.001" ixy="0.0" ixz="0.0"
               iyy="0.001" iyz="0.0"
               izz="0.001" />
    </inertial>
  </link>

  <joint name="camera_joint" type="fixed">
    <origin xyz="0.04 0 0.02" rpy="3.14159 -1.570796 0"/>
    <parent link="base_link"/>
    <child link="main_camera_optical"/>
  </joint>
  <link name="main_camera_optical"/>

</robot>